$ python -m unittest tests.py
connecting to localhost port 10000
FC:\Users\ganyo\AppData\Local\Programs\Python\Python37\lib\unittest\case.py:656: ResourceWarning: unclosed <socket.socket fd=476, family=AddressFamily.AF_INET
, type=SocketKind.SOCK_STREAM, proto=6, laddr=('0.0.0.0', 49746)>
  outcome.errors.clear()
ResourceWarning: Enable tracemalloc to get the object allocation traceback
connecting to localhost port 10000
FC:\Users\ganyo\AppData\Local\Programs\Python\Python37\lib\unittest\case.py:656: ResourceWarning: unclosed <socket.socket fd=476, family=AddressFamily.AF_INET
, type=SocketKind.SOCK_STREAM, proto=6, laddr=('0.0.0.0', 49750)>
  outcome.errors.clear()
ResourceWarning: Enable tracemalloc to get the object allocation traceback

======================================================================
FAIL: test_long_message_echo (tests.EchoTestCase)
test that a message longer than 16 bytes echoes in 16-byte chunks
----------------------------------------------------------------------
Traceback (most recent call last):
  File "C:\Users\ganyo\Desktop\Python_UW\py_230\L02\assignment\echo-server\tests.py", line 15, in send_message
    reply = client(message)
  File "C:\Users\ganyo\Desktop\Python_UW\py_230\L02\assignment\echo-server\echo_client.py", line 13, in client
    sock.connect(server_address)
ConnectionRefusedError: [WinError 10061] No connection could be made because the target machine actively refused it

During handling of the above exception, another exception occurred:

Traceback (most recent call last):
  File "C:\Users\ganyo\Desktop\Python_UW\py_230\L02\assignment\echo-server\tests.py", line 37, in test_long_message_echo
    actual = self.send_message(expected)
  File "C:\Users\ganyo\Desktop\Python_UW\py_230\L02\assignment\echo-server\tests.py", line 21, in send_message
    self.fail("Unexpected Error: {0}".format(str(e)))
AssertionError: Unexpected Error: [WinError 10061] No connection could be made because the target machine actively refused it

======================================================================
FAIL: test_short_message_echo (tests.EchoTestCase)
test that a message short than 16 bytes echoes cleanly
----------------------------------------------------------------------
Traceback (most recent call last):
  File "C:\Users\ganyo\Desktop\Python_UW\py_230\L02\assignment\echo-server\tests.py", line 15, in send_message
    reply = client(message)
  File "C:\Users\ganyo\Desktop\Python_UW\py_230\L02\assignment\echo-server\echo_client.py", line 13, in client
    sock.connect(server_address)
ConnectionRefusedError: [WinError 10061] No connection could be made because the target machine actively refused it

During handling of the above exception, another exception occurred:

Traceback (most recent call last):
  File "C:\Users\ganyo\Desktop\Python_UW\py_230\L02\assignment\echo-server\tests.py", line 27, in test_short_message_echo
    actual = self.send_message(expected)
  File "C:\Users\ganyo\Desktop\Python_UW\py_230\L02\assignment\echo-server\tests.py", line 21, in send_message
    self.fail("Unexpected Error: {0}".format(str(e)))
AssertionError: Unexpected Error: [WinError 10061] No connection could be made because the target machine actively refused it

----------------------------------------------------------------------
Ran 2 tests in 4.045s

FAILED (failures=2)
